<?xml version="1.0" encoding="UTF-8"?>
<testng-results skipped="0" failed="1" ignored="0" total="3" passed="2">
  <reporter-output>
  </reporter-output>
  <suite name="SmokeTests" duration-ms="94" started-at="2018-03-03T09:32:56Z" finished-at="2018-03-03T09:32:56Z">
    <groups>
    </groups>
    <test name="Tests" duration-ms="94" started-at="2018-03-03T09:32:56Z" finished-at="2018-03-03T09:32:56Z">
      <class name="com.testologic.tests.AddUsersTests">
        <test-method status="FAIL" signature="shouldAddUser()[pri:0, instance:com.testologic.tests.AddUsersTests@23ceabc1]" name="shouldAddUser" duration-ms="0" started-at="2018-03-03T09:32:56Z" finished-at="2018-03-03T09:32:56Z">
          <exception class="java.lang.AssertionError">
            <message>
              <![CDATA[failed test case]]>
            </message>
            <full-stacktrace>
              <![CDATA[java.lang.AssertionError: failed test case
at org.testng.Assert.fail(Assert.java:96)
at com.testologic.tests.AddUsersTests.shouldAddUser(AddUsersTests.java:11)
at sun.reflect.NativeMethodAccessorImpl.invoke0(Native Method)
at sun.reflect.NativeMethodAccessorImpl.invoke(Unknown Source)
at sun.reflect.DelegatingMethodAccessorImpl.invoke(Unknown Source)
at java.lang.reflect.Method.invoke(Unknown Source)
at org.testng.internal.MethodInvocationHelper.invokeMethod(MethodInvocationHelper.java:124)
at org.testng.internal.Invoker.invokeMethod(Invoker.java:580)
at org.testng.internal.Invoker.invokeTestMethod(Invoker.java:716)
at org.testng.internal.Invoker.invokeTestMethods(Invoker.java:988)
at org.testng.internal.TestMethodWorker.invokeTestMethods(TestMethodWorker.java:125)
at org.testng.internal.TestMethodWorker.run(TestMethodWorker.java:109)
at org.testng.TestRunner.privateRun(TestRunner.java:648)
at org.testng.TestRunner.run(TestRunner.java:505)
at org.testng.SuiteRunner.runTest(SuiteRunner.java:455)
at org.testng.SuiteRunner.runSequentially(SuiteRunner.java:450)
at org.testng.SuiteRunner.privateRun(SuiteRunner.java:415)
at org.testng.SuiteRunner.run(SuiteRunner.java:364)
at org.testng.SuiteRunnerWorker.runSuite(SuiteRunnerWorker.java:52)
at org.testng.SuiteRunnerWorker.run(SuiteRunnerWorker.java:84)
at org.testng.TestNG.runSuitesSequentially(TestNG.java:1208)
at org.testng.TestNG.runSuitesLocally(TestNG.java:1137)
at org.testng.TestNG.runSuites(TestNG.java:1049)
at org.testng.TestNG.run(TestNG.java:1017)
at org.testng.remote.AbstractRemoteTestNG.run(AbstractRemoteTestNG.java:114)
at org.testng.remote.RemoteTestNG.initAndRun(RemoteTestNG.java:251)
at org.testng.remote.RemoteTestNG.main(RemoteTestNG.java:77)
]]>
            </full-stacktrace>
          </exception> <!-- java.lang.AssertionError -->
          <reporter-output>
          </reporter-output>
        </test-method> <!-- shouldAddUser -->
      </class> <!-- com.testologic.tests.AddUsersTests -->
      <class name="com.testologic.tests.LoginTests">
        <test-method status="PASS" signature="ShouldFailedLogin()[pri:0, instance:com.testologic.tests.LoginTests@215be6bb]" name="ShouldFailedLogin" duration-ms="0" started-at="2018-03-03T09:32:56Z" finished-at="2018-03-03T09:32:56Z">
          <reporter-output>
          </reporter-output>
        </test-method> <!-- ShouldFailedLogin -->
        <test-method status="PASS" signature="shouldLoginSuccessfully()[pri:0, instance:com.testologic.tests.LoginTests@215be6bb]" name="shouldLoginSuccessfully" duration-ms="0" started-at="2018-03-03T09:32:56Z" finished-at="2018-03-03T09:32:56Z">
          <reporter-output>
          </reporter-output>
        </test-method> <!-- shouldLoginSuccessfully -->
      </class> <!-- com.testologic.tests.LoginTests -->
    </test> <!-- Tests -->
  </suite> <!-- SmokeTests -->
</testng-results>
